Workbook

Sheet DASHBOARD
A1: 📊 DASHBOARD EJECUTIVO — Control de Credenciales BEX | Actualización automática
A3: INDICADORES CLAVE ▸ Calculados en tiempo real
A4: TOTAL CREDENCIALES | D4: ASIGNADAS | G4: DISPONIBLES | J4: POR ASIGNAR | M4: ⚠️ PERDIDAS
A5: =COUNTA(ACTIVOS!$A$4:$A$130) -> 127 | D5: =COUNTIF(ACTIVOS!$C$4:$C$130,"ASIGNADO") -> 76 | G5: =COUNTIF(ACTIVOS!$C$4:$C$130,"DISPONIBLE") -> 15 | J5: =COUNTIF(ACTIVOS!$C$4:$C$130,"POR ASIGNAR") -> 35 | M5: =COUNTIF(ACTIVOS!$C$4:$C$130,"PERDIDO") -> 1
A7: INDICADORES DE PERSONAL
A8: TOTAL PERSONAL | D8: ACTIVOS | G8: INACTIVOS | J8: SUPERVISORES | M8: ⚠️ ALERTAS CRITICAS
A9: =COUNTA(PERSONAL!$A$4:$A$134) -> 131 | D9: =COUNTIF(PERSONAL!$G$4:$G$134,"ACTIVO") -> 95 | G9: =COUNTIF(PERSONAL!$G$4:$G$134,"INACTIVO") -> 36 | J9: =COUNTIF(PERSONAL!$D$4:$D$134,"SUPERVISOR") -> 16 | M9: =COUNTIF(PERSONAL!$J$4:$J$134,"*⚠️*") -> 4
A12: CREDENCIALES POR REGIONAL | I12: CREDENCIALES POR SUPERVISOR
A13: REGIONAL | B13: ASIGNADO | C13: DISPONIBLE | D13: POR ASIGNAR | E13: PERDIDO | F13: TOTAL | G13: % ASIG. | I13: SUPERVISOR | J13: REGIONAL | K13: ASIGNADO | L13: TOTAL | M13: INACTIVOS | N13: % ACTIV.
A14: COCHABAMBA | B14: =COUNTIFS(ACTIVOS!$F$4:$F$130,A14,ACTIVOS!$C$4:$C$130,"ASIGNADO") -> 18 | C14: =COUNTIFS(ACTIVOS!$F$4:$F$130,A14,ACTIVOS!$C$4:$C$130,"DISPONIBLE") -> 2 | D14: =COUNTIFS(ACTIVOS!$F$4:$F$130,A14,ACTIVOS!$C$4:$C$130,"POR ASIGNAR") -> 10 | E14: =COUNTIFS(ACTIVOS!$F$4:$F$130,A14,ACTIVOS!$C$4:$C$130,"PERDIDO") -> 0 | F14: =SUM(B14:E14) -> 30 | G14: =IFERROR(B14/F14,0) -> 0.6 | I14: HASIRA DANIELA OSINAGA CHOQUE | J14: COCHABAMBA | K14: =COUNTIFS(ACTIVOS!$E$4:$E$130,I14,ACTIVOS!$C$4:$C$130,"ASIGNADO") -> 9 | L14: =COUNTIF(ACTIVOS!$E$4:$E$130,I14) -> 9 | M14: =COUNTIFS(PERSONAL!$E$4:$E$134,I14,PERSONAL!$G$4:$G$134,"INACTIVO") -> 0 | N14: =IFERROR(C14/D14,0) -> 0.2
A15: LA PAZ | B15: =COUNTIFS(ACTIVOS!$F$4:$F$130,A15,ACTIVOS!$C$4:$C$130,"ASIGNADO") -> 29 | C15: =COUNTIFS(ACTIVOS!$F$4:$F$130,A15,ACTIVOS!$C$4:$C$130,"DISPONIBLE") -> 0 | D15: =COUNTIFS(ACTIVOS!$F$4:$F$130,A15,ACTIVOS!$C$4:$C$130,"POR ASIGNAR") -> 10 | E15: =COUNTIFS(ACTIVOS!$F$4:$F$130,A15,ACTIVOS!$C$4:$C$130,"PERDIDO") -> 0 | F15: =SUM(B15:E15) -> 39 | G15: =IFERROR(B15/F15,0) -> 0.74358974 | I15: PAMELA FANNY CALANI LAURA | J15: COCHABAMBA | K15: =COUNTIFS(ACTIVOS!$E$4:$E$130,I15,ACTIVOS!$C$4:$C$130,"ASIGNADO") -> 9 | L15: =COUNTIF(ACTIVOS!$E$4:$E$130,I15) -> 11 | M15: =COUNTIFS(PERSONAL!$E$4:$E$134,I15,PERSONAL!$G$4:$G$134,"INACTIVO") -> 0 | N15: =IFERROR(C15/D15,0) -> 0
A16: ORURO | B16: =COUNTIFS(ACTIVOS!$F$4:$F$130,A16,ACTIVOS!$C$4:$C$130,"ASIGNADO") -> 10 | C16: =COUNTIFS(ACTIVOS!$F$4:$F$130,A16,ACTIVOS!$C$4:$C$130,"DISPONIBLE") -> 0 | D16: =COUNTIFS(ACTIVOS!$F$4:$F$130,A16,ACTIVOS!$C$4:$C$130,"POR ASIGNAR") -> 0 | E16: =COUNTIFS(ACTIVOS!$F$4:$F$130,A16,ACTIVOS!$C$4:$C$130,"PERDIDO") -> 0 | F16: =SUM(B16:E16) -> 10 | G16: =IFERROR(B16/F16,0) -> 1 | I16: NATALIA VILLARROEL | J16: COCHABAMBA | K16: =COUNTIFS(ACTIVOS!$E$4:$E$130,I16,ACTIVOS!$C$4:$C$130,"ASIGNADO") -> 0 | L16: =COUNTIF(ACTIVOS!$E$4:$E$130,I16) -> 10 | M16: =COUNTIFS(PERSONAL!$E$4:$E$134,I16,PERSONAL!$G$4:$G$134,"INACTIVO") -> 0 | N16: =IFERROR(C16/D16,0) -> 0
A17: SANTA CRUZ | B17: =COUNTIFS(ACTIVOS!$F$4:$F$130,A17,ACTIVOS!$C$4:$C$130,"ASIGNADO") -> 13 | C17: =COUNTIFS(ACTIVOS!$F$4:$F$130,A17,ACTIVOS!$C$4:$C$130,"DISPONIBLE") -> 13 | D17: =COUNTIFS(ACTIVOS!$F$4:$F$130,A17,ACTIVOS!$C$4:$C$130,"POR ASIGNAR") -> 8 | E17: =COUNTIFS(ACTIVOS!$F$4:$F$130,A17,ACTIVOS!$C$4:$C$130,"PERDIDO") -> 1 | F17: =SUM(B17:E17) -> 35 | G17: =IFERROR(B17/F17,0) -> 0.37142857 | I17: CLAUDIA SHASKIA CALLE NINA | J17: LA PAZ | K17: =COUNTIFS(ACTIVOS!$E$4:$E$130,I17,ACTIVOS!$C$4:$C$130,"ASIGNADO") -> 7 | L17: =COUNTIF(ACTIVOS!$E$4:$E$130,I17) -> 7 | M17: =COUNTIFS(PERSONAL!$E$4:$E$134,I17,PERSONAL!$G$4:$G$134,"INACTIVO") -> 1 | N17: =IFERROR(C17/D17,0) -> 1.625
A18: SUCRE | B18: =COUNTIFS(ACTIVOS!$F$4:$F$130,A18,ACTIVOS!$C$4:$C$130,"ASIGNADO") -> 6 | C18: =COUNTIFS(ACTIVOS!$F$4:$F$130,A18,ACTIVOS!$C$4:$C$130,"DISPONIBLE") -> 0 | D18: =COUNTIFS(ACTIVOS!$F$4:$F$130,A18,ACTIVOS!$C$4:$C$130,"POR ASIGNAR") -> 0 | E18: =COUNTIFS(ACTIVOS!$F$4:$F$130,A18,ACTIVOS!$C$4:$C$130,"PERDIDO") -> 0 | F18: =SUM(B18:E18) -> 6 | G18: =IFERROR(B18/F18,0) -> 1 | I18: GERCY EVER ERGUETA KIPPES | J18: LA PAZ | K18: =COUNTIFS(ACTIVOS!$E$4:$E$130,I18,ACTIVOS!$C$4:$C$130,"ASIGNADO") -> 5 | L18: =COUNTIF(ACTIVOS!$E$4:$E$130,I18) -> 5 | M18: =COUNTIFS(PERSONAL!$E$4:$E$134,I18,PERSONAL!$G$4:$G$134,"INACTIVO") -> 12 | N18: =IFERROR(C18/D18,0) -> 0
A19: TARIJA | B19: =COUNTIFS(ACTIVOS!$F$4:$F$130,A19,ACTIVOS!$C$4:$C$130,"ASIGNADO") -> 0 | C19: =COUNTIFS(ACTIVOS!$F$4:$F$130,A19,ACTIVOS!$C$4:$C$130,"DISPONIBLE") -> 0 | D19: =COUNTIFS(ACTIVOS!$F$4:$F$130,A19,ACTIVOS!$C$4:$C$130,"POR ASIGNAR") -> 7 | E19: =COUNTIFS(ACTIVOS!$F$4:$F$130,A19,ACTIVOS!$C$4:$C$130,"PERDIDO") -> 0 | F19: =SUM(B19:E19) -> 7 | G19: =IFERROR(B19/F19,0) -> 0 | I19: JOEL DAVID HUANCA HUANCA | J19: LA PAZ | K19: =COUNTIFS(ACTIVOS!$E$4:$E$130,I19,ACTIVOS!$C$4:$C$130,"ASIGNADO") -> 7 | L19: =COUNTIF(ACTIVOS!$E$4:$E$130,I19) -> 7 | M19: =COUNTIFS(PERSONAL!$E$4:$E$134,I19,PERSONAL!$G$4:$G$134,"INACTIVO") -> 1 | N19: =IFERROR(C19/D19,0) -> 0
A20: TOTAL GENERAL | B20: =SUM(B14:B19) -> 76 | C20: =SUM(C14:C19) -> 15 | D20: =SUM(D14:D19) -> 35 | E20: =SUM(E14:E19) -> 1 | F20: =SUM(F14:F19) -> 127 | G20: =IFERROR(B20/F20,0) -> 0.5984252 | I20: MAGALI YESENIA HUANCA HUANCA | J20: LA PAZ | K20: =COUNTIFS(ACTIVOS!$E$4:$E$130,I20,ACTIVOS!$C$4:$C$130,"ASIGNADO") -> 0 | L20: =COUNTIF(ACTIVOS!$E$4:$E$130,I20) -> 0 | M20: =COUNTIFS(PERSONAL!$E$4:$E$134,I20,PERSONAL!$G$4:$G$134,"INACTIVO") -> 4 | N20: =IFERROR(C20/D20,0) -> 0.42857143
I21: MILENKO ADRIANA ORDONEZ NUNEZ | J21: LA PAZ | K21: =COUNTIFS(ACTIVOS!$E$4:$E$130,I21,ACTIVOS!$C$4:$C$130,"ASIGNADO") -> 10 | L21: =COUNTIF(ACTIVOS!$E$4:$E$130,I21) -> 10 | M21: =COUNTIFS(PERSONAL!$E$4:$E$134,I21,PERSONAL!$G$4:$G$134,"INACTIVO") -> 6 | N21: =IFERROR(C21/D21,0) -> 0
I22: LIONEL CHABUR | J22: LA PAZ | K22: =COUNTIFS(ACTIVOS!$E$4:$E$130,I22,ACTIVOS!$C$4:$C$130,"ASIGNADO") -> 0 | L22: =COUNTIF(ACTIVOS!$E$4:$E$130,I22) -> 10 | M22: =COUNTIFS(PERSONAL!$E$4:$E$134,I22,PERSONAL!$G$4:$G$134,"INACTIVO") -> 0 | N22: =IFERROR(C22/D22,0) -> 0
I23: MIRIAM ROSA CHAMBI QUISPE | J23: ORURO | K23: =COUNTIFS(ACTIVOS!$E$4:$E$130,I23,ACTIVOS!$C$4:$C$130,"ASIGNADO") -> 10 | L23: =COUNTIF(ACTIVOS!$E$4:$E$130,I23) -> 10 | M23: =COUNTIFS(PERSONAL!$E$4:$E$134,I23,PERSONAL!$G$4:$G$134,"INACTIVO") -> 3 | N23: =IFERROR(C23/D23,0) -> 0
I24: JORGE SAAVEDRA | J24: SANTA CRUZ | K24: =COUNTIFS(ACTIVOS!$E$4:$E$130,I24,ACTIVOS!$C$4:$C$130,"ASIGNADO") -> 1 | L24: =COUNTIF(ACTIVOS!$E$4:$E$130,I24) -> 1 | M24: =COUNTIFS(PERSONAL!$E$4:$E$134,I24,PERSONAL!$G$4:$G$134,"INACTIVO") -> 0 | N24: =IFERROR(C24/D24,0) -> 0
I25: BEATRIZ OVIEDO OVIEDO | J25: SANTA CRUZ | K25: =COUNTIFS(ACTIVOS!$E$4:$E$130,I25,ACTIVOS!$C$4:$C$130,"ASIGNADO") -> 6 | L25: =COUNTIF(ACTIVOS!$E$4:$E$130,I25) -> 8 | M25: =COUNTIFS(PERSONAL!$E$4:$E$134,I25,PERSONAL!$G$4:$G$134,"INACTIVO") -> 6 | N25: =IFERROR(C25/D25,0) -> 0
I26: DELIA JORDAN FACUSSE | J26: SANTA CRUZ | K26: =COUNTIFS(ACTIVOS!$E$4:$E$130,I26,ACTIVOS!$C$4:$C$130,"ASIGNADO") -> 0 | L26: =COUNTIF(ACTIVOS!$E$4:$E$130,I26) -> 0 | M26: =COUNTIFS(PERSONAL!$E$4:$E$134,I26,PERSONAL!$G$4:$G$134,"INACTIVO") -> 0 | N26: =IFERROR(C26/D26,0) -> 0
I27: JOSE GUTIERREZ PEDRAZA | J27: SANTA CRUZ | K27: =COUNTIFS(ACTIVOS!$E$4:$E$130,I27,ACTIVOS!$C$4:$C$130,"ASIGNADO") -> 3 | L27: =COUNTIF(ACTIVOS!$E$4:$E$130,I27) -> 3 | M27: =COUNTIFS(PERSONAL!$E$4:$E$134,I27,PERSONAL!$G$4:$G$134,"INACTIVO") -> 0 | N27: =IFERROR(C27/D27,0) -> 0
I28: JENNY CRISTINA ECHALAR MONTALVO | J28: SUCRE | K28: =COUNTIFS(ACTIVOS!$E$4:$E$130,I28,ACTIVOS!$C$4:$C$130,"ASIGNADO") -> 6 | L28: =COUNTIF(ACTIVOS!$E$4:$E$130,I28) -> 6 | M28: =COUNTIFS(PERSONAL!$E$4:$E$134,I28,PERSONAL!$G$4:$G$134,"INACTIVO") -> 0 | N28: =IFERROR(C28/D28,0) -> 0
I29: MARIA FERNANDA DAZA PALMA | J29: TARIJA | K29: =COUNTIFS(ACTIVOS!$E$4:$E$130,I29,ACTIVOS!$C$4:$C$130,"ASIGNADO") -> 0 | L29: =COUNTIF(ACTIVOS!$E$4:$E$130,I29) -> 0 | M29: =COUNTIFS(PERSONAL!$E$4:$E$134,I29,PERSONAL!$G$4:$G$134,"INACTIVO") -> 3 | N29: =IFERROR(C29/D29,0) -> 0
A32: 📋 ÚLTIMOS MOVIMIENTOS REGISTRADOS
A33: N° MOV | B33: FECHA | C33: TIPO MOVIMIENTO | D33: CÓDIGO BEX | E33: AFILIADOR | F33: SUPERVISOR | G33: REGIONAL
A34: MOV-0040 | B34: 46176 | C34: ENTREGA INICIAL | D34: BEX-2039 | E34: CESAR OSCAR LAURA CHUYMA | F34: JOEL DAVID HUANCA HUANCA | G34: LA PAZ
A35: MOV-0041 | B35: 46176 | C35: ENTREGA INICIAL | D35: BEX-2040 | E35: MILENKO ADRIANA ORDONEZ NUNEZ | F35: MILENKO ADRIANA ORDONEZ NUNEZ | G35: LA PAZ
A36: MOV-0042 | B36: 46176 | C36: ENTREGA INICIAL | D36: BEX-2041 | E36: RUTH CELINA PONCE PACO | F36: MILENKO ADRIANA ORDONEZ NUNEZ | G36: LA PAZ
A37: MOV-0043 | B37: 46176 | C37: ENTREGA INICIAL | D37: BEX-2042 | E37: SILVANA ASUNCION ORDONEZ NUNEZ | F37: MILENKO ADRIANA ORDONEZ NUNEZ | G37: LA PAZ
A38: MOV-0044 | B38: 46176 | C38: ENTREGA INICIAL | D38: BEX-2043 | E38: ADILSON ALMANZA GOMEZ | F38: MIRIAM ROSA CHAMBI QUISPE | G38: ORURO
A39: MOV-0045 | B39: 46176 | C39: ENTREGA INICIAL | D39: BEX-2044 | E39: ARACELI MARLENE TAPIA GUERRA | F39: MIRIAM ROSA CHAMBI QUISPE | G39: ORURO
A40: MOV-0046 | B40: 46176 | C40: ENTREGA INICIAL | D40: BEX-2045 | E40: BRENDA XIMENA BARBA VACA | F40: BEATRIZ OVIEDO OVIEDO | G40: SANTA CRUZ
A41: MOV-0047 | B41: 46176 | C41: ENTREGA INICIAL | D41: BEX-2046 | E41: MARCO ANTONIO ESCOBAR ALVAREZ | F41: BEATRIZ OVIEDO OVIEDO | G41: SANTA CRUZ
A42: MOV-0048 | B42: 46176 | C42: PERDIDA | D42: BEX-0518 | E42: MARCO ANTONIO ESCOBAR ALVAREZ | F42: BEATRIZ OVIEDO OVIEDO | G42: SANTA CRUZ
A43: MOV-0049 | B43: 46176 | C43: PERDIDA | D43: BEX-2045 | E43: BRENDA XIMENA BARBA VACA | F43: BEATRIZ OVIEDO OVIEDO | G43: SANTA CRUZ

Sheet BUSCADOR
A1: 🔍 BUSCADOR INTELIGENTE DE ACTIVOS — Sistema BEX
A3: BUSCAR POR: | G3: ← Escriba aquí el código BEX, nombre o teléfono
A5: 📋 RESULTADO — BÚSQUEDA POR CÓDIGO BEX
B6: CÓDIGO BEX: | C6: =IFERROR(_xludf.xlookup(C3,ACTIVOS!$A$4:$A$130,ACTIVOS!$A$4:$A$130,"NO ENCONTRADO"),"NO ENCONTRADO") -> NO ENCONTRADO
B7: GENERACIÓN: | C7: =IFERROR(_xludf.xlookup(C3,ACTIVOS!$A$4:$A$130,ACTIVOS!$B$4:$B$130,"—"),"—") -> —
B8: ESTADO: | C8: =IFERROR(_xludf.xlookup(C3,ACTIVOS!$A$4:$A$130,ACTIVOS!$C$4:$C$130,"—"),"—") -> —
B9: RESPONSABLE ACTUAL: | C9: =IFERROR(_xludf.xlookup(C3,ACTIVOS!$A$4:$A$130,ACTIVOS!$D$4:$D$130,"—"),"—") -> —
B10: SUPERVISOR: | C10: =IFERROR(_xludf.xlookup(C3,ACTIVOS!$A$4:$A$130,ACTIVOS!$E$4:$E$130,"—"),"—") -> —
B11: REGIONAL: | C11: =IFERROR(_xludf.xlookup(C3,ACTIVOS!$A$4:$A$130,ACTIVOS!$F$4:$F$130,"—"),"—") -> —
B12: FECHA ENTREGA: | C12: =IFERROR(_xludf.xlookup(C3,ACTIVOS!$A$4:$A$130,ACTIVOS!$G$4:$G$130,"—"),"—") -> —
B13: DÍAS EN USO: | C13: =IFERROR(_xludf.xlookup(C3,ACTIVOS!$A$4:$A$130,ACTIVOS!$H$4:$H$130,"—"),"—") -> —
B14: OBSERVACIONES: | C14: =IFERROR(_xludf.xlookup(C3,ACTIVOS!$A$4:$A$130,ACTIVOS!$I$4:$I$130,"—"),"—") -> —
A16: 👤 RESULTADO — BÚSQUEDA POR NOMBRE / TELÉFONO
B17: NOMBRE COMPLETO: | C17: =IFERROR(_xludf.xlookup(C3,PERSONAL!$C$4:$C$134,PERSONAL!$C$4:$C$134,IFERROR(_xludf.xlookup(C3,PERSONAL!$B$4:$B$134,PERSONAL!$C$4:$C$134,"NO ENCONTRADO"),"NO ENCONTRADO")),"NO ENCONTRADO") -> NO ENCONTRADO
B18: TELÉFONO: | C18: =IFERROR(_xludf.xlookup(C3,PERSONAL!$C$4:$C$134,PERSONAL!$B$4:$B$134,IFERROR(_xludf.xlookup(C3,PERSONAL!$B$4:$B$134,PERSONAL!$B$4:$B$134,"—"),"—")),"—") -> —
B19: ROL: | C19: =IFERROR(_xludf.xlookup(C3,PERSONAL!$C$4:$C$134,PERSONAL!$D$4:$D$134,IFERROR(_xludf.xlookup(C3,PERSONAL!$B$4:$B$134,PERSONAL!$D$4:$D$134,"—"),"—")),"—") -> —
B20: SUPERVISOR: | C20: =IFERROR(_xludf.xlookup(C3,PERSONAL!$C$4:$C$134,PERSONAL!$E$4:$E$134,IFERROR(_xludf.xlookup(C3,PERSONAL!$B$4:$B$134,PERSONAL!$E$4:$E$134,"—"),"—")),"—") -> —
B21: REGIONAL: | C21: =IFERROR(_xludf.xlookup(C3,PERSONAL!$C$4:$C$134,PERSONAL!$F$4:$F$134,IFERROR(_xludf.xlookup(C3,PERSONAL!$B$4:$B$134,PERSONAL!$F$4:$F$134,"—"),"—")),"—") -> —
B22: ESTADO: | C22: =IFERROR(_xludf.xlookup(C3,PERSONAL!$C$4:$C$134,PERSONAL!$G$4:$G$134,IFERROR(_xludf.xlookup(C3,PERSONAL!$B$4:$B$134,PERSONAL!$G$4:$G$134,"—"),"—")),"—") -> —
B23: ACTIVO ACTUAL: | C23: =IFERROR(_xludf.xlookup(C3,PERSONAL!$C$4:$C$134,PERSONAL!$H$4:$H$134,IFERROR(_xludf.xlookup(C3,PERSONAL!$B$4:$B$134,PERSONAL!$H$4:$H$134,"—"),"—")),"—") -> —
B24: OBSERVACIONES: | C24: =IFERROR(_xludf.xlookup(C3,PERSONAL!$C$4:$C$134,PERSONAL!$J$4:$J$134,IFERROR(_xludf.xlookup(C3,PERSONAL!$B$4:$B$134,PERSONAL!$J$4:$J$134,"—"),"—")),"—") -> —
A26: 📋 HISTORIAL DE MOVIMIENTOS PARA ESTA ACTIVO
A27: N° MOV | B27: FECHA | C27: TIPO | D27: CÓDIGO BEX | E27: AFILIADOR | F27: SUPERVISOR | G27: REGIONAL | H27: OBSERVACIONES
A28: ℹ️ Para ver el historial completo de movimientos de esta credencial, filtre la hoja MOVIMIENTOS por el código BEX buscado. Use el filtro automático en la columna 'CÓDIGO BEX'. También puede usar la función FILTRAR en Excel 365: =FILTER(MOVIMIENTOS!A4:I200, MOVIMIENTOS!D4:D200=C3, "Sin movimientos")
A34: 💡 INSTRUCCIONES DE USO: • Escriba en la celda C3 el código BEX exacto (ej: BEX-0152) para buscar una credencial • Escriba el nombre de la persona para buscar en PERSONAL • Los resultados se actualizan automáticamente al escribir

Sheet PERSONAL
A1: 👤 TABLA MAESTRA DE PERSONAL — Sistema BEX Control de Credenciales
A3: ID PERSONA | B3: TELÉFONO (ID ÚNICO) | C3: NOMBRES Y APELLIDOS | D3: ROL | E3: SUPERVISOR | F3: REGIONAL | G3: ESTADO | H3: CREDENCIAL ACTUAL | I3: FECHA INGRESO | J3: OBSERVACIONES
A4: PER-001 | B4: POR REGISTRAR | C4: HASIRA DANIELA OSINAGA CHOQUE | D4: SUPERVISOR | E4: HASIRA DANIELA OSINAGA CHOQUE | F4: COCHABAMBA | G4: ACTIVO | H4: BEX-0298
A5: PER-002 | B5: POR REGISTRAR | C5: BRUNO ROCHA PEREIRA | D5: AFILIADOR | E5: HASIRA DANIELA OSINAGA CHOQUE | F5: COCHABAMBA | G5: ACTIVO | H5: BEX-0152
A6: PER-003 | B6: POR REGISTRAR | C6: JOSE OLAF ROJAS CONDARCO | D6: AFILIADOR | E6: HASIRA DANIELA OSINAGA CHOQUE | F6: COCHABAMBA | G6: ACTIVO | H6: BEX-0532
A7: PER-004 | B7: POR REGISTRAR | C7: EVELYN CARMELA ESPINOZA CASTRO | D7: AFILIADOR | E7: HASIRA DANIELA OSINAGA CHOQUE | F7: COCHABAMBA | G7: ACTIVO | H7: BEX-0511
A8: PER-005 | B8: POR REGISTRAR | C8: HEYDY DAYANA PUTARE MACHACA | D8: AFILIADOR | E8: HASIRA DANIELA OSINAGA CHOQUE | F8: COCHABAMBA | G8: ACTIVO | H8: BEX-0528
A9: PER-006 | B9: POR REGISTRAR | C9: JOHANNA CASSANDRA CHAVEZ VALERIANO | D9: AFILIADOR | E9: HASIRA DANIELA OSINAGA CHOQUE | F9: COCHABAMBA | G9: ACTIVO | H9: BEX-0522
A10: PER-007 | B10: POR REGISTRAR | C10: LAURA ANDREA TRIBENO GUTIERREZ | D10: AFILIADOR | E10: HASIRA DANIELA OSINAGA CHOQUE | F10: COCHABAMBA | G10: ACTIVO | H10: BEX-0533
A11: PER-008 | B11: POR REGISTRAR | C11: MARCELO RIVAS MARIN | D11: AFILIADOR | E11: HASIRA DANIELA OSINAGA CHOQUE | F11: COCHABAMBA | G11: ACTIVO | H11: BEX-0525
A12: PER-009 | B12: POR REGISTRAR | C12: SARAI VANESA TERAN GONZALES | D12: AFILIADOR | E12: HASIRA DANIELA OSINAGA CHOQUE | F12: COCHABAMBA | G12: ACTIVO | H12: BEX-0517
A13: PER-010 | B13: POR REGISTRAR | C13: PAMELA FANNY CALANI LAURA | D13: SUPERVISOR | E13: PAMELA FANNY CALANI LAURA | F13: COCHABAMBA | G13: ACTIVO | H13: BEX-0017
A14: PER-011 | B14: POR REGISTRAR | C14: ALAN GUSTAVO ARNEZ TORO | D14: AFILIADOR | E14: PAMELA FANNY CALANI LAURA | F14: COCHABAMBA | G14: ACTIVO | H14: BEX-0014
A15: PER-012 | B15: POR REGISTRAR | C15: CALEB HERNAN FLORES FLORES | D15: AFILIADOR | E15: PAMELA FANNY CALANI LAURA | F15: COCHABAMBA | G15: ACTIVO | H15: BEX-0057
... A17: PER-014 | B17: POR REGISTRAR | C17: PABLO SANTIAGO PEREZ NAVA | D17: AFILIADOR | E17: PAMELA FANNY CALANI LAURA | F17: COCHABAMBA | G17: ACTIVO | H17: BEX-0023
A18: PER-015 | B18: POR REGISTRAR | C18: ROSIELVA ALDANA | D18: AFILIADOR | E18: PAMELA FANNY CALANI LAURA | F18: COCHABAMBA | G18: ACTIVO | H18: BEX-0012 | J18: Nombre incompleto - verificar
A19: PER-016 | B19: POR REGISTRAR | C19: VANIA GRAGEDA ESPINOZA | D19: AFILIADOR | E19: PAMELA FANNY CALANI LAURA | F19: COCHABAMBA | G19: ACTIVO | H19: BEX-0013
A20: PER-017 | B20: POR REGISTRAR | C20: VLADIMIR SUTURI TOCOCARI | D20: AFILIADOR | E20: PAMELA FANNY CALANI LAURA | F20: COCHABAMBA | G20: ACTIVO | H20: BEX-0011
A21: PER-018 | B21: POR REGISTRAR | C21: JHOJAN JAIRO CALLAHUARA CHOQUE | D21: AFILIADOR | E21: PAMELA FANNY CALANI LAURA | F21: COCHABAMBA | G21: ACTIVO | H21: BEX-0020
A22: PER-019 | B22: POR REGISTRAR | C22: NATALIA VILLARROEL | D22: SUPERVISOR | E22: NATALIA VILLARROEL | F22: COCHABAMBA | G22: ACTIVO | J22: Supervisor registrado en ENTREGADOS - datos incompletos
A23: PER-020 | B23: POR REGISTRAR | C23: CLAUDIA SHASKIA CALLE NINA | D23: SUPERVISOR | E23: CLAUDIA SHASKIA CALLE NINA | F23: LA PAZ | G23: ACTIVO | H23: BEX-0176 | J23: ⚠️ BEX-0176 DUPLICADO - verificar con REYNA IVONNE
A24: PER-021 | B24: POR REGISTRAR | C24: AARON PEDRO CHUQUIMIA CHAIRA | D24: AFILIADOR | E24: CLAUDIA SHASKIA CALLE NINA | F24: LA PAZ | G24: ACTIVO | H24: BEX-0162
A25: PER-022 | B25: POR REGISTRAR | C25: EIMI SONIA CHUQUIMIA CHAIRA | D25: AFILIADOR | E25: CLAUDIA SHASKIA CALLE NINA | F25: LA PAZ | G25: ACTIVO | H25: BEX-0112
A26: PER-023 | B26: POR REGISTRAR | C26: LUZ NATALIA HUANAPACO PENA | D26: AFILIADOR | E26: CLAUDIA SHASKIA CALLE NINA | F26: LA PAZ | G26: INACTIVO
A27: PER-024 | B27: POR REGISTRAR | C27: MIGUEL ANGEL BLANCO RONDO | D27: AFILIADOR | E27: CLAUDIA SHASKIA CALLE NINA | F27: LA PAZ | G27: ACTIVO | H27: BEX-0169
A28: PER-025 | B28: POR REGISTRAR | C28: REYNA IVONNE CALLE NINA | D28: AFILIADOR | E28: CLAUDIA SHASKIA CALLE NINA | F28: LA PAZ | G28: ACTIVO | H28: BEX-0176 | J28: ⚠️ BEX-0176 DUPLICADO - misma credencial que CLAUDIA SHASKIA
A29: PER-026 | B29: POR REGISTRAR | C29: RUBEN ANTONIO HINOJOSA TUPA | D29: AFILIADOR | E29: CLAUDIA SHASKIA CALLE NINA | F29: LA PAZ | G29: ACTIVO | H29: BEX-0120
A30: PER-027 | B30: POR REGISTRAR | C30: SAMIEL ARTURO TORRICOS VILLARREAL | D30: AFILIADOR | E30: CLAUDIA SHASKIA CALLE NINA | F30: LA PAZ | G30: ACTIVO | H30: BEX-0151
A31: PER-028 | B31: POR REGISTRAR | C31: DANIELA LUCERO FLAVIA MIRANDA | D31: AFILIADOR | E31: CLAUDIA SHASKIA CALLE NINA | F31: LA PAZ | G31: ACTIVO | H31: BEX-0368
A32: PER-029 | B32: POR REGISTRAR | C32: GERCY EVER ERGUETA KIPPES | D32: SUPERVISOR | E32: GERCY EVER ERGUETA KIPPES | F32: LA PAZ | G32: ACTIVO | H32: BEX-2038 | J32: Nueva credencial asignada
A33: PER-030 | B33: POR REGISTRAR | C33: ABIGAIL HUANACO TICONA | D33: AFILIADOR | E33: GERCY EVER ERGUETA KIPPES | F33: LA PAZ | G33: INACTIVO
A34: PER-031 | B34: POR REGISTRAR | C34: ALEXIA MICAELA ERGUETA ALIAGA | D34: AFILIADOR | E34: GERCY EVER ERGUETA KIPPES | F34: LA PAZ | G34: ACTIVO | H34: BEX-2037
A35: PER-032 | B35: POR REGISTRAR | C35: ALVARO CIMAR MAMANI PRADO | D35: AFILIADOR | E35: GERCY EVER ERGUETA KIPPES | F35: LA PAZ | G35: INACTIVO
A36: PER-033 | B36: POR REGISTRAR | C36: ANA GABRIELA CONDORI HERRERA | D36: AFILIADOR | E36: GERCY EVER ERGUETA KIPPES | F36: LA PAZ | G36: INACTIVO
A37: PER-034 | B37: POR REGISTRAR | C37: BENJAMIN CHUQUIMIA CORDERO | D37: AFILIADOR | E37: GERCY EVER ERGUETA KIPPES | F37: LA PAZ | G37: INACTIVO
A38: PER-035 | B38: POR REGISTRAR | C38: DARING ACARAPI MAMANI | D38: AFILIADOR | E38: GERCY EVER ERGUETA KIPPES | F38: LA PAZ | G38: ACTIVO | H38: BEX-0184
A39: PER-036 | B39: POR REGISTRAR | C39: GIOVANA TOLA CASACA | D39: AFILIADOR | E39: GERCY EVER ERGUETA KIPPES | F39: LA PAZ | G39: INACTIVO
A40: PER-037 | B40: POR REGISTRAR | C40: HARRY JHONNY CRUZ MALLQUI | D40: AFILIADOR | E40: GERCY EVER ERGUETA KIPPES | F40: LA PAZ | G40: INACTIVO
A41: PER-038 | B41: POR REGISTRAR | C41: JHOSELYN DANIELA MANZANEDA CHINO | D41: AFILIADOR | E41: GERCY EVER ERGUETA KIPPES | F41: LA PAZ | G41: INACTIVO
A42: PER-039 | B42: POR REGISTRAR | C42: LAURA VANESSA QUISPE MAMANI | D42: AFILIADOR | E42: GERCY EVER ERGUETA KIPPES | F42: LA PAZ | G42: INACTIVO
...

Sheet ACTIVOS
A1: 🪪 TABLA MAESTRA DE ACTIVOS — Sistema BEX Control de Credenciales
A3: CÓDIGO BEX | B3: GENERACIÓN | C3: ESTADO CREDENCIAL | D3: RESPONSABLE ACTUAL | E3: SUPERVISOR | F3: REGIONAL | G3: FECHA ENTREGA | H3: DÍAS EN USO | I3: OBSERVACIONES
A4: BEX-0011 | B4: LEGACY (BEX-0xxx) | C4: ASIGNADO | D4: VLADIMIR SUTURI TOCOCARI | E4: PAMELA FANNY CALANI LAURA | F4: COCHABAMBA | H4: —
A5: BEX-0012 | B5: LEGACY (BEX-0xxx) | C5: ASIGNADO | D5: ROSIELVA ALDANA | E5: PAMELA FANNY CALANI LAURA | F5: COCHABAMBA | H5: —
A6: BEX-0013 | B6: LEGACY (BEX-0xxx) | C6: ASIGNADO | D6: VANIA GRAGEDA ESPINOZA | E6: PAMELA FANNY CALANI LAURA | F6: COCHABAMBA | H6: —
A7: BEX-0014 | B7: LEGACY (BEX-0xxx) | C7: ASIGNADO | D7: ALAN GUSTAVO ARNEZ TORO | E7: PAMELA FANNY CALANI LAURA | F7: COCHABAMBA | H7: —
A8: BEX-0015 | B8: LEGACY (BEX-0xxx) | C8: DISPONIBLE | D8: NO ASIGNADO | E8: PAMELA FANNY CALANI LAURA | F8: COCHABAMBA | H8: —
A9: BEX-0017 | B9: LEGACY (BEX-0xxx) | C9: ASIGNADO | D9: PAMELA FANNY CALANI LAURA | E9: PAMELA FANNY CALANI LAURA | F9: COCHABAMBA | H9: —
A10: BEX-0018 | B10: LEGACY (BEX-0xxx) | C10: ASIGNADO | D10: DIEGO ARMANDO COLQUE COLQUE | E10: PAMELA FANNY CALANI LAURA | F10: COCHABAMBA | H10: —
A11: BEX-0020 | B11: LEGACY (BEX-0xxx) | C11: ASIGNADO | D11: JHOJAN JAIRO CALLAHUARA CHOQUE | E11: PAMELA FANNY CALANI LAURA | F11: COCHABAMBA | H11: —
A12: BEX-0023 | B12: LEGACY (BEX-0xxx) | C12: ASIGNADO | D12: PABLO SANTIAGO PEREZ NAVA | E12: PAMELA FANNY CALANI LAURA | F12: COCHABAMBA | H12: —
A13: BEX-0027 | B13: LEGACY (BEX-0xxx) | C13: ASIGNADO | D13: JHENIFER LUCERO SERRUDO LLAMPA | E13: JENNY CRISTINA ECHALAR MONTALVO | F13: SUCRE | H13: —
A14: BEX-0033 | B14: LEGACY (BEX-0xxx) | C14: DISPONIBLE | D14: NO ASIGNADO | E14: PAMELA FANNY CALANI LAURA | F14: COCHABAMBA | H14: —
A15: BEX-0057 | B15: LEGACY (BEX-0xxx) | C15: ASIGNADO | D15: CALEB HERNAN FLORES FLORES | E15: PAMELA FANNY CALANI LAURA | F15: COCHABAMBA | H15: —
A16: BEX-0106 | B16: LEGACY (BEX-0xxx) | C16: ASIGNADO | D16: CAMILA LOZA MERINO / JHOSEP SHARUM QUISBERT | E16: GERCY EVER ERGUETA KIPPES | F16: LA PAZ | H16: — | I16: ⚠️ DUPLICADO CRITICO: Mismo codigo asignado a 2 personas en equipos distintos
A17: BEX-0107 | B17: LEGACY (BEX-0xxx) | C17: ASIGNADO | D17: JHOSEP QUISBERT MAMANI | E17: GERCY EVER ERGUETA KIPPES | F17: LA PAZ | H17: —
A18: BEX-0109 | B18: LEGACY (BEX-0xxx) | C18: ASIGNADO | D18: JHOANA IVETH VARGAS COPA | E18: JOEL DAVID HUANCA HUANCA | F18: LA PAZ | H18: —
A19: BEX-0111 | B19: LEGACY (BEX-0xxx) | C19: ASIGNADO | D19: WILSON ALFREDO MACHACA CALCINA | E19: JOEL DAVID HUANCA HUANCA | F19: LA PAZ | H19: —
A20: BEX-0112 | B20: LEGACY (BEX-0xxx) | C20: ASIGNADO | D20: EIMI SONIA CHUQUIMIA CHAIRA | E20: CLAUDIA SHASKIA CALLE NINA | F20: LA PAZ | H20: —
A21: BEX-0113 | B21: LEGACY (BEX-0xxx) | C21: ASIGNADO | D21: MIRIAM ROSA CHAMBI QUISPE | E21: MIRIAM ROSA CHAMBI QUISPE | F21: ORURO | H21: —
A22: BEX-0114 | B22: LEGACY (BEX-0xxx) | C22: ASIGNADO | D22: LUZ MARIBEL VIRACA TAQUIMALLCO | E22: MIRIAM ROSA CHAMBI QUISPE | F22: ORURO | H22: —
A23: BEX-0115 | B23: LEGACY (BEX-0xxx) | C23: ASIGNADO | D23: ZULMA FLORES CARICARI | E23: MIRIAM ROSA CHAMBI QUISPE | F23: ORURO | H23: —
A24: BEX-0116 | B24: LEGACY (BEX-0xxx) | C24: ASIGNADO | D24: GIMENA MELVIS HUANCA GOMEZ | E24: MIRIAM ROSA CHAMBI QUISPE | F24: ORURO | H24: —
A25: BEX-0117 | B25: LEGACY (BEX-0xxx) | C25: ASIGNADO | D25: RICHAR YAMIL AVAREZ CANAVIRI | E25: MIRIAM ROSA CHAMBI QUISPE | F25: ORURO | H25: —
A26: BEX-0118 | B26: LEGACY (BEX-0xxx) | C26: ASIGNADO | D26: CRUZ TORRICO TATIANA CRISTINA | E26: MIRIAM ROSA CHAMBI QUISPE | F26: ORURO | H26: —
A27: BEX-0119 | B27: LEGACY (BEX-0xxx) | C27: ASIGNADO | D27: CAROLINA KIMBERLY QUISPE ARANCIBIA | E27: MIRIAM ROSA CHAMBI QUISPE | F27: ORURO | H27: —
A28: BEX-0120 | B28: LEGACY (BEX-0xxx) | C28: ASIGNADO | D28: RUBEN ANTONIO HINOJOSA TUPA | E28: CLAUDIA SHASKIA CALLE NINA | F28: LA PAZ | H28: —
... A38: BEX-0158 | B38: LEGACY (BEX-0xxx) | C38: ASIGNADO | D38: JOEL DAVID HUANCA HUANCA | E38: JOEL DAVID HUANCA HUANCA | F38: LA PAZ | H38: —
A39: BEX-0162 | B39: LEGACY (BEX-0xxx) | C39: ASIGNADO | D39: AARON PEDRO CHUQUIMIA CHAIRA | E39: CLAUDIA SHASKIA CALLE NINA | F39: LA PAZ | H39: — | I39: Normalizado de BEX-162
A40: BEX-0166 | B40: LEGACY (BEX-0xxx) | C40: ASIGNADO | D40: KATTERIN VANESA MEDRANO ESPEJO | E40: MILENKO ADRIANA ORDONEZ NUNEZ | F40: LA PAZ | H40: —
A41: BEX-0167 | B41: LEGACY (BEX-0xxx) | C41: ASIGNADO | D41: ADRIANA ALEJANDRA AREVALO HERBAS | E41: MILENKO ADRIANA ORDONEZ NUNEZ | F41: LA PAZ | H41: —
A42: BEX-0169 | B42: LEGACY (BEX-0xxx) | C42: ASIGNADO | D42: MIGUEL ANGEL BLANCO RONDO | E42: CLAUDIA SHASKIA CALLE NINA | F42: LA PAZ | H42: —
A43: BEX-0176 | B43: LEGACY (BEX-0xxx) | C43: ASIGNADO | D43: CLAUDIA SHASKIA CALLE NINA / REYNA IVONNE CALLE NINA | E43: CLAUDIA SHASKIA CALLE NINA | F43: LA PAZ | H43: — | I43: ⚠️ DUPLICADO CRITICO: Mismo codigo asignado a 2 personas
A44: BEX-0179 | B44: LEGACY (BEX-0xxx) | C44: ASIGNADO | D44: MARIA EMILIA HUAYLLA ALMANZA | E44: MILENKO ADRIANA ORDONEZ NUNEZ | F44: LA PAZ | H44: —
A45: BEX-0184 | B45: LEGACY (BEX-0xxx) | C45: ASIGNADO | D45: DARING ACARAPI MAMANI | E45: GERCY EVER ERGUETA KIPPES | F45: LA PAZ | H45: — | I45: Normalizado de BEX-184
A46: BEX-0186 | B46: LEGACY (BEX-0xxx) | C46: ASIGNADO | D46: DANIELA ANDREA VARGAS AREVALO | E46: MILENKO ADRIANA ORDONEZ NUNEZ | F46: LA PAZ | H46: —
A47: BEX-0187 | B47: LEGACY (BEX-0xxx) | C47: ASIGNADO | D47: VANESSA ILLANES YUJRA | E47: JOEL DAVID HUANCA HUANCA | F47: LA PAZ | H47: —
A48: BEX-0192 | B48: LEGACY (BEX-0xxx) | C48: ASIGNADO | D48: FRANZ RODRIGO LEVANDRO PANUNI | E48: JOEL DAVID HUANCA HUANCA | F48: LA PAZ | H48: —
A49: BEX-0195 | B49: LEGACY (BEX-0xxx) | C49: DISPONIBLE | D49: LORENA (INACTIVO) | E49: BEATRIZ OVIEDO OVIEDO | F49: SANTA CRUZ | H49: — | I49: Persona inactiva - nombre incompleto
A50: BEX-0196 | B50: LEGACY (BEX-0xxx) | C50: ASIGNADO | D50: BEATRIZ OVIEDO OVIEDO | E50: BEATRIZ OVIEDO OVIEDO | F50: SANTA CRUZ | H50: —
...

Sheet MOVIMIENTOS
A1: 📋 HISTORIAL DE MOVIMIENTOS — Registro Permanente e Inmutable
A3: N° MOV | B3: FECHA | C3: TIPO MOVIMIENTO | D3: CÓDIGO BEX | E3: AFILIADOR | F3: SUPERVISOR | G3: REGIONAL | H3: OBSERVACIONES | I3: REGISTRADO POR
A4: MOV-0001 | B4: 46169 | C4: ENTREGA INICIAL | D4: BEX-2000 | E4: JORGE SAAVEDRA | F4: JORGE SAAVEDRA | G4: SANTA CRUZ | H4: Lote inaugural entregado a supervisor | I4: SISTEMA
A5: MOV-0002 | B5: 46169 | C5: ENTREGA INICIAL | D5: BEX-2001 | E5: POR ASIGNAR | F5: DELIA JORDAN | G5: SANTA CRUZ | I5: SISTEMA
A6: MOV-0003 | B6: 46169 | C6: ENTREGA INICIAL | D6: BEX-2002 | E6: POR ASIGNAR | F6: DELIA JORDAN | G6: SANTA CRUZ | I6: SISTEMA
A7: MOV-0004 | B7: 46169 | C7: ENTREGA INICIAL | D7: BEX-2003 | E7: POR ASIGNAR | F7: DELIA JORDAN | G7: SANTA CRUZ | I7: SISTEMA
A8: MOV-0005 | B8: 46169 | C8: ENTREGA INICIAL | D8: BEX-2004 | E8: POR ASIGNAR | F8: DELIA JORDAN | G8: SANTA CRUZ | I8: SISTEMA
A9: MOV-0006 | B9: 46169 | C9: ENTREGA INICIAL | D9: BEX-2005 | E9: POR ASIGNAR | F9: DELIA JORDAN | G9: SANTA CRUZ | I9: SISTEMA
A10: MOV-0007 | B10: 46174 | C10: ENTREGA INICIAL | D10: BEX-2006 | E10: POR ASIGNAR | F10: JOSE GUTIERREZ | G10: SANTA CRUZ | I10: SISTEMA
A11: MOV-0008 | B11: 46174 | C11: ENTREGA INICIAL | D11: BEX-2007 | E11: POR ASIGNAR | F11: JOSE GUTIERREZ | G11: SANTA CRUZ | I11: SISTEMA
A12: MOV-0009 | B12: 46174 | C12: ENTREGA INICIAL | D12: BEX-2008 | E12: POR ASIGNAR | F12: JOSE GUTIERREZ | G12: SANTA CRUZ | I12: SISTEMA
A13: MOV-0010 | B13: 46174 | C13: ENTREGA INICIAL | D13: BEX-2009 | E13: POR ASIGNAR | F13: JOSE GUTIERREZ | G13: SANTA CRUZ | I13: SISTEMA
A14: MOV-0011 | B14: 46175 | C14: ENTREGA INICIAL | D14: BEX-2010 | E14: POR ASIGNAR | F14: MARIA FERNANDA DAZA | G14: TARIJA | I14: SISTEMA
A15: MOV-0012 | B15: 46175 | C15: ENTREGA INICIAL | D15: BEX-2011 | E15: POR ASIGNAR | F15: MARIA FERNANDA DAZA | G15: TARIJA | I15: SISTEMA
A16: MOV-0013 | B16: 46175 | C16: ENTREGA INICIAL | D16: BEX-2012 | E16: POR ASIGNAR | F16: MARIA FERNANDA DAZA | G16: TARIJA | I16: SISTEMA
... A48: MOV-0045 | B48: 46176 | C48: ENTREGA INICIAL | D48: BEX-2044 | E48: ARACELI MARLENE TAPIA GUERRA | F48: MIRIAM ROSA CHAMBI QUISPE | G48: ORURO | I48: SISTEMA
A49: MOV-0046 | B49: 46176 | C49: ENTREGA INICIAL | D49: BEX-2045 | E49: BRENDA XIMENA BARBA VACA | F49: BEATRIZ OVIEDO OVIEDO | G49: SANTA CRUZ | H49: Reposicion por perdida | I49: SISTEMA
A50: MOV-0047 | B50: 46176 | C50: ENTREGA INICIAL | D50: BEX-2046 | E50: MARCO ANTONIO ESCOBAR ALVAREZ | F50: BEATRIZ OVIEDO OVIEDO | G50: SANTA CRUZ | H50: Reposicion - perdio BEX-0518 | I50: SISTEMA
A51: MOV-0048 | B51: 46176 | C51: PERDIDA | D51: BEX-0518 | E51: MARCO ANTONIO ESCOBAR ALVAREZ | F51: BEATRIZ OVIEDO OVIEDO | G51: SANTA CRUZ | H51: COBRAR POR PERDIDA | I51: SISTEMA
A52: MOV-0049 | B52: 46176 | C52: PERDIDA | D52: BEX-2045 | E52: BRENDA XIMENA BARBA VACA | F52: BEATRIZ OVIEDO OVIEDO | G52: SANTA CRUZ | H52: Credencial anterior perdida - COBRAR | I52: SISTEMA

Sheet PARAMETROS
A1: ⚙ PARÁMETROS DEL SISTEMA — BEX Control de Credenciales
A3: REGIONALES | B3: ESTADOS PERSONA | C3: ROLES | D3: ESTADOS CREDENCIAL | E3: TIPOS DE MOVIMIENTO | F3: GENERACION | H3: ⚠ ERRORES CRÍTICOS DETECTADOS
A4: COCHABAMBA | B4: ACTIVO | C4: AFILIADOR | D4: ASIGNADO | E4: ENTREGA INICIAL | F4: NUEVA (BEX-2xxx) | H4: 1. BEX-0176 asignado a DOS personas: CLAUDIA SHASKIA y REYNA IVONNE
A5: LA PAZ | B5: INACTIVO | C5: SUPERVISOR | D5: DISPONIBLE | E5: ASIGNACION | F5: LEGACY (BEX-0xxx) | H5: 2. BEX-0106 posiblemente duplicado: CAMILA LOZA (GERCY) y JHOSEP SHARUM (MAGALI)
A6: ORURO | D6: POR ASIGNAR | E6: DEVOLUCION | H6: 3. 3 personas con nombres incompletos: TOMAS, LORENA, SELMA
A7: SANTA CRUZ | D7: PERDIDO | E7: PERDIDA | H7: 4. BEX-0518 reportada como PERDIDA - pendiente cobro a MARCO ESCOBAR
A8: SUCRE | D8: EN TRAMITE | E8: REPOSICION | H8: 5. SUPERVISORES sin datos en hoja principal: LIONEL CHABUR, NATALIA VILLARROEL
A9: TARIJA | E9: CAMBIO SUPERVISOR | H9: 6. Codigos normalizados (espacios y ceros): BEX-162, BEX- 0176, BEX-027, etc.
E10: CAMBIO REGIONAL | H10: 7. Todos los telefonos marcados como POR REGISTRAR - campo critico faltante
E11: BAJA
